{
 "cells": [
  {
   "cell_type": "code",
   "execution_count": 21,
   "metadata": {},
   "outputs": [],
   "source": [
    "import pandas as pd\n",
    "import tensorflow as tf \n",
    "\n",
    "train_data = pd.read_csv('/code/mnist/train.csv')\n",
    "test_data = pd.read_csv('/code/mnist/test.csv')\n",
    "\n",
    "X = train_data.drop('label', axis=1)\n",
    "Y = train_data['label']"
   ]
  },
  {
   "cell_type": "code",
   "execution_count": 22,
   "metadata": {},
   "outputs": [],
   "source": [
    "X = X.astype('float32') / 255\n",
    "test_data = test_data.astype('float32') / 255\n",
    "\n",
    "Y = tf.keras.utils.to_categorical(Y, 10)"
   ]
  },
  {
   "cell_type": "code",
   "execution_count": 23,
   "metadata": {},
   "outputs": [],
   "source": [
    "train_x = X[:round(X.shape[0] * 0.8)]\n",
    "check_x = X[round(X.shape[0] * 0.8):]\n",
    "\n",
    "train_y = Y[:round(Y.shape[0] * 0.8)]\n",
    "check_y = Y[round(Y.shape[0] * 0.8):]"
   ]
  },
  {
   "cell_type": "code",
   "execution_count": 24,
   "metadata": {},
   "outputs": [],
   "source": [
    "# from tensorflow.keras.layers import Dense, Dropout\n",
    "\n",
    "# inputs = tf.keras.Input(shape=(784,))\n",
    "# x_1 = Dense(256, activation='relu')(inputs)\n",
    "# x_2 = Dropout(0.2)(x_1)\n",
    "# outputs = Dense(10, activation='softmax')(x_2)\n",
    "\n",
    "# model = tf.keras.Model(inputs=inputs, outputs=outputs, name='mnist_model')"
   ]
  },
  {
   "cell_type": "code",
   "execution_count": 25,
   "metadata": {},
   "outputs": [],
   "source": [
    "train_x = train_x.values.reshape(-1, 28, 28, 1)\n",
    "check_x = check_x.values.reshape(-1, 28, 28, 1)\n",
    "\n",
    "test_data = test_data.values.reshape(-1, 28, 28, 1)"
   ]
  },
  {
   "cell_type": "code",
   "execution_count": 26,
   "metadata": {},
   "outputs": [
    {
     "data": {
      "text/plain": [
       "(33600, 28, 28, 1)"
      ]
     },
     "execution_count": 26,
     "metadata": {},
     "output_type": "execute_result"
    }
   ],
   "source": [
    "train_x.shape"
   ]
  },
  {
   "cell_type": "code",
   "execution_count": 27,
   "metadata": {},
   "outputs": [],
   "source": [
    "from tensorflow.keras.layers import Dense, Dropout, Conv2D, MaxPooling2D, Flatten\n",
    "\n",
    "\n",
    "inputs = tf.keras.Input(shape=(28, 28, 1))\n",
    "x_1 = Conv2D(32, kernel_size=(5, 5), strides=1, activation='relu', padding='same')(inputs)\n",
    "x_2 = MaxPooling2D(pool_size=(2, 2), strides=2, padding='same')(x_1)\n",
    "x_3 = Flatten()(x_2)\n",
    "x_4 = Dropout(0.4)(x_3)\n",
    "outputs = Dense(10, activation='softmax')(x_4)\n",
    "\n",
    "model = tf.keras.Model(inputs=inputs, outputs=outputs, name='mnist_model')"
   ]
  },
  {
   "cell_type": "code",
   "execution_count": 28,
   "metadata": {},
   "outputs": [],
   "source": [
    "LEARNING_RATE = 0.001\n",
    "model.compile(\n",
    "    optimizer=tf.keras.optimizers.Adam(),\n",
    "    loss=tf.keras.losses.categorical_crossentropy,\n",
    "    metrics=[tf.keras.metrics.categorical_accuracy],\n",
    ")"
   ]
  },
  {
   "cell_type": "code",
   "execution_count": 29,
   "metadata": {},
   "outputs": [
    {
     "data": {
      "text/plain": [
       "(33600, 10)"
      ]
     },
     "execution_count": 29,
     "metadata": {},
     "output_type": "execute_result"
    }
   ],
   "source": [
    "train_y.shape"
   ]
  },
  {
   "cell_type": "code",
   "execution_count": 30,
   "metadata": {},
   "outputs": [
    {
     "name": "stdout",
     "output_type": "stream",
     "text": [
      "Epoch 1/20\n"
     ]
    },
    {
     "name": "stderr",
     "output_type": "stream",
     "text": [
      "2023-08-14 23:45:07.499036: E tensorflow/compiler/xla/stream_executor/cuda/cuda_dnn.cc:425] Loaded runtime CuDNN library: 8.1.1 but source was compiled with: 8.6.0.  CuDNN library needs to have matching major version and equal or higher minor version. If using a binary install, upgrade your CuDNN library.  If building from sources, make sure the library loaded at runtime is compatible with the version specified during compile configuration.\n",
      "2023-08-14 23:45:07.500502: W tensorflow/core/framework/op_kernel.cc:1828] OP_REQUIRES failed at conv_ops_fused_impl.h:625 : UNIMPLEMENTED: DNN library is not found.\n"
     ]
    },
    {
     "ename": "UnimplementedError",
     "evalue": "Graph execution error:\n\nDetected at node 'mnist_model/conv2d_2/Relu' defined at (most recent call last):\n    File \"/usr/lib/python3.8/runpy.py\", line 194, in _run_module_as_main\n      return _run_code(code, main_globals, None,\n    File \"/usr/lib/python3.8/runpy.py\", line 87, in _run_code\n      exec(code, run_globals)\n    File \"/usr/local/lib/python3.8/dist-packages/ipykernel_launcher.py\", line 17, in <module>\n      app.launch_new_instance()\n    File \"/usr/local/lib/python3.8/dist-packages/traitlets/config/application.py\", line 1043, in launch_instance\n      app.start()\n    File \"/usr/local/lib/python3.8/dist-packages/ipykernel/kernelapp.py\", line 736, in start\n      self.io_loop.start()\n    File \"/usr/local/lib/python3.8/dist-packages/tornado/platform/asyncio.py\", line 195, in start\n      self.asyncio_loop.run_forever()\n    File \"/usr/lib/python3.8/asyncio/base_events.py\", line 570, in run_forever\n      self._run_once()\n    File \"/usr/lib/python3.8/asyncio/base_events.py\", line 1859, in _run_once\n      handle._run()\n    File \"/usr/lib/python3.8/asyncio/events.py\", line 81, in _run\n      self._context.run(self._callback, *self._args)\n    File \"/usr/local/lib/python3.8/dist-packages/ipykernel/kernelbase.py\", line 516, in dispatch_queue\n      await self.process_one()\n    File \"/usr/local/lib/python3.8/dist-packages/ipykernel/kernelbase.py\", line 505, in process_one\n      await dispatch(*args)\n    File \"/usr/local/lib/python3.8/dist-packages/ipykernel/kernelbase.py\", line 412, in dispatch_shell\n      await result\n    File \"/usr/local/lib/python3.8/dist-packages/ipykernel/kernelbase.py\", line 740, in execute_request\n      reply_content = await reply_content\n    File \"/usr/local/lib/python3.8/dist-packages/ipykernel/ipkernel.py\", line 422, in do_execute\n      res = shell.run_cell(\n    File \"/usr/local/lib/python3.8/dist-packages/ipykernel/zmqshell.py\", line 546, in run_cell\n      return super().run_cell(*args, **kwargs)\n    File \"/usr/local/lib/python3.8/dist-packages/IPython/core/interactiveshell.py\", line 3009, in run_cell\n      result = self._run_cell(\n    File \"/usr/local/lib/python3.8/dist-packages/IPython/core/interactiveshell.py\", line 3064, in _run_cell\n      result = runner(coro)\n    File \"/usr/local/lib/python3.8/dist-packages/IPython/core/async_helpers.py\", line 129, in _pseudo_sync_runner\n      coro.send(None)\n    File \"/usr/local/lib/python3.8/dist-packages/IPython/core/interactiveshell.py\", line 3269, in run_cell_async\n      has_raised = await self.run_ast_nodes(code_ast.body, cell_name,\n    File \"/usr/local/lib/python3.8/dist-packages/IPython/core/interactiveshell.py\", line 3448, in run_ast_nodes\n      if await self.run_code(code, result, async_=asy):\n    File \"/usr/local/lib/python3.8/dist-packages/IPython/core/interactiveshell.py\", line 3508, in run_code\n      exec(code_obj, self.user_global_ns, self.user_ns)\n    File \"/tmp/ipykernel_1446/3480129598.py\", line 20, in <module>\n      history = model.fit(train_x, train_y, batch_size=BATCH_SIZE, epochs=EPOCHS, validation_split=VALIDATION_SPLIT, callbacks=callbacks)\n    File \"/usr/local/lib/python3.8/dist-packages/keras/src/utils/traceback_utils.py\", line 65, in error_handler\n      return fn(*args, **kwargs)\n    File \"/usr/local/lib/python3.8/dist-packages/keras/src/engine/training.py\", line 1742, in fit\n      tmp_logs = self.train_function(iterator)\n    File \"/usr/local/lib/python3.8/dist-packages/keras/src/engine/training.py\", line 1338, in train_function\n      return step_function(self, iterator)\n    File \"/usr/local/lib/python3.8/dist-packages/keras/src/engine/training.py\", line 1322, in step_function\n      outputs = model.distribute_strategy.run(run_step, args=(data,))\n    File \"/usr/local/lib/python3.8/dist-packages/keras/src/engine/training.py\", line 1303, in run_step\n      outputs = model.train_step(data)\n    File \"/usr/local/lib/python3.8/dist-packages/keras/src/engine/training.py\", line 1080, in train_step\n      y_pred = self(x, training=True)\n    File \"/usr/local/lib/python3.8/dist-packages/keras/src/utils/traceback_utils.py\", line 65, in error_handler\n      return fn(*args, **kwargs)\n    File \"/usr/local/lib/python3.8/dist-packages/keras/src/engine/training.py\", line 569, in __call__\n      return super().__call__(*args, **kwargs)\n    File \"/usr/local/lib/python3.8/dist-packages/keras/src/utils/traceback_utils.py\", line 65, in error_handler\n      return fn(*args, **kwargs)\n    File \"/usr/local/lib/python3.8/dist-packages/keras/src/engine/base_layer.py\", line 1150, in __call__\n      outputs = call_fn(inputs, *args, **kwargs)\n    File \"/usr/local/lib/python3.8/dist-packages/keras/src/utils/traceback_utils.py\", line 96, in error_handler\n      return fn(*args, **kwargs)\n    File \"/usr/local/lib/python3.8/dist-packages/keras/src/engine/functional.py\", line 512, in call\n      return self._run_internal_graph(inputs, training=training, mask=mask)\n    File \"/usr/local/lib/python3.8/dist-packages/keras/src/engine/functional.py\", line 669, in _run_internal_graph\n      outputs = node.layer(*args, **kwargs)\n    File \"/usr/local/lib/python3.8/dist-packages/keras/src/utils/traceback_utils.py\", line 65, in error_handler\n      return fn(*args, **kwargs)\n    File \"/usr/local/lib/python3.8/dist-packages/keras/src/engine/base_layer.py\", line 1150, in __call__\n      outputs = call_fn(inputs, *args, **kwargs)\n    File \"/usr/local/lib/python3.8/dist-packages/keras/src/utils/traceback_utils.py\", line 96, in error_handler\n      return fn(*args, **kwargs)\n    File \"/usr/local/lib/python3.8/dist-packages/keras/src/layers/convolutional/base_conv.py\", line 321, in call\n      return self.activation(outputs)\n    File \"/usr/local/lib/python3.8/dist-packages/keras/src/activations.py\", line 321, in relu\n      return backend.relu(\n    File \"/usr/local/lib/python3.8/dist-packages/keras/src/backend.py\", line 5397, in relu\n      x = tf.nn.relu(x)\nNode: 'mnist_model/conv2d_2/Relu'\nDNN library is not found.\n\t [[{{node mnist_model/conv2d_2/Relu}}]] [Op:__inference_train_function_2503]",
     "output_type": "error",
     "traceback": [
      "\u001b[0;31m---------------------------------------------------------------------------\u001b[0m",
      "\u001b[0;31mUnimplementedError\u001b[0m                        Traceback (most recent call last)",
      "Cell \u001b[0;32mIn[30], line 20\u001b[0m\n\u001b[1;32m     17\u001b[0m EPOCHS \u001b[39m=\u001b[39m \u001b[39m20\u001b[39m\n\u001b[1;32m     18\u001b[0m VALIDATION_SPLIT \u001b[39m=\u001b[39m \u001b[39m0.2\u001b[39m\n\u001b[0;32m---> 20\u001b[0m history \u001b[39m=\u001b[39m model\u001b[39m.\u001b[39;49mfit(train_x, train_y, batch_size\u001b[39m=\u001b[39;49mBATCH_SIZE, epochs\u001b[39m=\u001b[39;49mEPOCHS, validation_split\u001b[39m=\u001b[39;49mVALIDATION_SPLIT, callbacks\u001b[39m=\u001b[39;49mcallbacks)\n\u001b[1;32m     21\u001b[0m model\u001b[39m.\u001b[39msave(\u001b[39m'\u001b[39m\u001b[39m/code/mnist/mnist_model.h5\u001b[39m\u001b[39m'\u001b[39m)\n",
      "File \u001b[0;32m/usr/local/lib/python3.8/dist-packages/keras/src/utils/traceback_utils.py:70\u001b[0m, in \u001b[0;36mfilter_traceback.<locals>.error_handler\u001b[0;34m(*args, **kwargs)\u001b[0m\n\u001b[1;32m     67\u001b[0m     filtered_tb \u001b[39m=\u001b[39m _process_traceback_frames(e\u001b[39m.\u001b[39m__traceback__)\n\u001b[1;32m     68\u001b[0m     \u001b[39m# To get the full stack trace, call:\u001b[39;00m\n\u001b[1;32m     69\u001b[0m     \u001b[39m# `tf.debugging.disable_traceback_filtering()`\u001b[39;00m\n\u001b[0;32m---> 70\u001b[0m     \u001b[39mraise\u001b[39;00m e\u001b[39m.\u001b[39mwith_traceback(filtered_tb) \u001b[39mfrom\u001b[39;00m \u001b[39mNone\u001b[39;00m\n\u001b[1;32m     71\u001b[0m \u001b[39mfinally\u001b[39;00m:\n\u001b[1;32m     72\u001b[0m     \u001b[39mdel\u001b[39;00m filtered_tb\n",
      "File \u001b[0;32m/usr/local/lib/python3.8/dist-packages/tensorflow/python/eager/execute.py:53\u001b[0m, in \u001b[0;36mquick_execute\u001b[0;34m(op_name, num_outputs, inputs, attrs, ctx, name)\u001b[0m\n\u001b[1;32m     51\u001b[0m \u001b[39mtry\u001b[39;00m:\n\u001b[1;32m     52\u001b[0m   ctx\u001b[39m.\u001b[39mensure_initialized()\n\u001b[0;32m---> 53\u001b[0m   tensors \u001b[39m=\u001b[39m pywrap_tfe\u001b[39m.\u001b[39mTFE_Py_Execute(ctx\u001b[39m.\u001b[39m_handle, device_name, op_name,\n\u001b[1;32m     54\u001b[0m                                       inputs, attrs, num_outputs)\n\u001b[1;32m     55\u001b[0m \u001b[39mexcept\u001b[39;00m core\u001b[39m.\u001b[39m_NotOkStatusException \u001b[39mas\u001b[39;00m e:\n\u001b[1;32m     56\u001b[0m   \u001b[39mif\u001b[39;00m name \u001b[39mis\u001b[39;00m \u001b[39mnot\u001b[39;00m \u001b[39mNone\u001b[39;00m:\n",
      "\u001b[0;31mUnimplementedError\u001b[0m: Graph execution error:\n\nDetected at node 'mnist_model/conv2d_2/Relu' defined at (most recent call last):\n    File \"/usr/lib/python3.8/runpy.py\", line 194, in _run_module_as_main\n      return _run_code(code, main_globals, None,\n    File \"/usr/lib/python3.8/runpy.py\", line 87, in _run_code\n      exec(code, run_globals)\n    File \"/usr/local/lib/python3.8/dist-packages/ipykernel_launcher.py\", line 17, in <module>\n      app.launch_new_instance()\n    File \"/usr/local/lib/python3.8/dist-packages/traitlets/config/application.py\", line 1043, in launch_instance\n      app.start()\n    File \"/usr/local/lib/python3.8/dist-packages/ipykernel/kernelapp.py\", line 736, in start\n      self.io_loop.start()\n    File \"/usr/local/lib/python3.8/dist-packages/tornado/platform/asyncio.py\", line 195, in start\n      self.asyncio_loop.run_forever()\n    File \"/usr/lib/python3.8/asyncio/base_events.py\", line 570, in run_forever\n      self._run_once()\n    File \"/usr/lib/python3.8/asyncio/base_events.py\", line 1859, in _run_once\n      handle._run()\n    File \"/usr/lib/python3.8/asyncio/events.py\", line 81, in _run\n      self._context.run(self._callback, *self._args)\n    File \"/usr/local/lib/python3.8/dist-packages/ipykernel/kernelbase.py\", line 516, in dispatch_queue\n      await self.process_one()\n    File \"/usr/local/lib/python3.8/dist-packages/ipykernel/kernelbase.py\", line 505, in process_one\n      await dispatch(*args)\n    File \"/usr/local/lib/python3.8/dist-packages/ipykernel/kernelbase.py\", line 412, in dispatch_shell\n      await result\n    File \"/usr/local/lib/python3.8/dist-packages/ipykernel/kernelbase.py\", line 740, in execute_request\n      reply_content = await reply_content\n    File \"/usr/local/lib/python3.8/dist-packages/ipykernel/ipkernel.py\", line 422, in do_execute\n      res = shell.run_cell(\n    File \"/usr/local/lib/python3.8/dist-packages/ipykernel/zmqshell.py\", line 546, in run_cell\n      return super().run_cell(*args, **kwargs)\n    File \"/usr/local/lib/python3.8/dist-packages/IPython/core/interactiveshell.py\", line 3009, in run_cell\n      result = self._run_cell(\n    File \"/usr/local/lib/python3.8/dist-packages/IPython/core/interactiveshell.py\", line 3064, in _run_cell\n      result = runner(coro)\n    File \"/usr/local/lib/python3.8/dist-packages/IPython/core/async_helpers.py\", line 129, in _pseudo_sync_runner\n      coro.send(None)\n    File \"/usr/local/lib/python3.8/dist-packages/IPython/core/interactiveshell.py\", line 3269, in run_cell_async\n      has_raised = await self.run_ast_nodes(code_ast.body, cell_name,\n    File \"/usr/local/lib/python3.8/dist-packages/IPython/core/interactiveshell.py\", line 3448, in run_ast_nodes\n      if await self.run_code(code, result, async_=asy):\n    File \"/usr/local/lib/python3.8/dist-packages/IPython/core/interactiveshell.py\", line 3508, in run_code\n      exec(code_obj, self.user_global_ns, self.user_ns)\n    File \"/tmp/ipykernel_1446/3480129598.py\", line 20, in <module>\n      history = model.fit(train_x, train_y, batch_size=BATCH_SIZE, epochs=EPOCHS, validation_split=VALIDATION_SPLIT, callbacks=callbacks)\n    File \"/usr/local/lib/python3.8/dist-packages/keras/src/utils/traceback_utils.py\", line 65, in error_handler\n      return fn(*args, **kwargs)\n    File \"/usr/local/lib/python3.8/dist-packages/keras/src/engine/training.py\", line 1742, in fit\n      tmp_logs = self.train_function(iterator)\n    File \"/usr/local/lib/python3.8/dist-packages/keras/src/engine/training.py\", line 1338, in train_function\n      return step_function(self, iterator)\n    File \"/usr/local/lib/python3.8/dist-packages/keras/src/engine/training.py\", line 1322, in step_function\n      outputs = model.distribute_strategy.run(run_step, args=(data,))\n    File \"/usr/local/lib/python3.8/dist-packages/keras/src/engine/training.py\", line 1303, in run_step\n      outputs = model.train_step(data)\n    File \"/usr/local/lib/python3.8/dist-packages/keras/src/engine/training.py\", line 1080, in train_step\n      y_pred = self(x, training=True)\n    File \"/usr/local/lib/python3.8/dist-packages/keras/src/utils/traceback_utils.py\", line 65, in error_handler\n      return fn(*args, **kwargs)\n    File \"/usr/local/lib/python3.8/dist-packages/keras/src/engine/training.py\", line 569, in __call__\n      return super().__call__(*args, **kwargs)\n    File \"/usr/local/lib/python3.8/dist-packages/keras/src/utils/traceback_utils.py\", line 65, in error_handler\n      return fn(*args, **kwargs)\n    File \"/usr/local/lib/python3.8/dist-packages/keras/src/engine/base_layer.py\", line 1150, in __call__\n      outputs = call_fn(inputs, *args, **kwargs)\n    File \"/usr/local/lib/python3.8/dist-packages/keras/src/utils/traceback_utils.py\", line 96, in error_handler\n      return fn(*args, **kwargs)\n    File \"/usr/local/lib/python3.8/dist-packages/keras/src/engine/functional.py\", line 512, in call\n      return self._run_internal_graph(inputs, training=training, mask=mask)\n    File \"/usr/local/lib/python3.8/dist-packages/keras/src/engine/functional.py\", line 669, in _run_internal_graph\n      outputs = node.layer(*args, **kwargs)\n    File \"/usr/local/lib/python3.8/dist-packages/keras/src/utils/traceback_utils.py\", line 65, in error_handler\n      return fn(*args, **kwargs)\n    File \"/usr/local/lib/python3.8/dist-packages/keras/src/engine/base_layer.py\", line 1150, in __call__\n      outputs = call_fn(inputs, *args, **kwargs)\n    File \"/usr/local/lib/python3.8/dist-packages/keras/src/utils/traceback_utils.py\", line 96, in error_handler\n      return fn(*args, **kwargs)\n    File \"/usr/local/lib/python3.8/dist-packages/keras/src/layers/convolutional/base_conv.py\", line 321, in call\n      return self.activation(outputs)\n    File \"/usr/local/lib/python3.8/dist-packages/keras/src/activations.py\", line 321, in relu\n      return backend.relu(\n    File \"/usr/local/lib/python3.8/dist-packages/keras/src/backend.py\", line 5397, in relu\n      x = tf.nn.relu(x)\nNode: 'mnist_model/conv2d_2/Relu'\nDNN library is not found.\n\t [[{{node mnist_model/conv2d_2/Relu}}]] [Op:__inference_train_function_2503]"
     ]
    }
   ],
   "source": [
    "callbacks = [\n",
    "    tf.keras.callbacks.EarlyStopping(\n",
    "        patience=2, \n",
    "        restore_best_weights=True\n",
    "    ),\n",
    "    tf.keras.callbacks.ModelCheckpoint(\n",
    "        '/code/mnist/data/temp/mnist_sequential_{epoch:03d}_{val_loss:.4f}.h5',\n",
    "        save_best_only=True\n",
    "    ),\n",
    "    tf.keras.callbacks.TensorBoard(\n",
    "        log_dir='/code/mnist/logs',\n",
    "        histogram_freq=1\n",
    "    ),\n",
    "]\n",
    "\n",
    "BATCH_SIZE = 128\n",
    "EPOCHS = 20\n",
    "VALIDATION_SPLIT = 0.2\n",
    "\n",
    "history = model.fit(train_x, train_y, batch_size=BATCH_SIZE, epochs=EPOCHS, validation_split=VALIDATION_SPLIT, callbacks=callbacks)\n",
    "model.save('/code/mnist/mnist_model.h5')"
   ]
  },
  {
   "cell_type": "code",
   "execution_count": null,
   "metadata": {},
   "outputs": [],
   "source": [
    "model.summary()"
   ]
  },
  {
   "cell_type": "code",
   "execution_count": null,
   "metadata": {},
   "outputs": [],
   "source": [
    "model.evaluate(check_x, check_y)"
   ]
  },
  {
   "cell_type": "markdown",
   "metadata": {},
   "source": [
    "- 0.9811905026435852\n",
    "- 0.98416668176651 maxpooling\n",
    "- 0.9783333539962769 karnel(5,5) => (3,3) & padding 'same'\n",
    "- 0.9825000166893005 karnel => (3,3)\n",
    "- 0.9840475916862488 drop 0.2 => 0.4"
   ]
  },
  {
   "cell_type": "code",
   "execution_count": null,
   "metadata": {},
   "outputs": [],
   "source": [
    "submit = pd.DataFrame()\n",
    "submit['ImageId'] = [i for i in range (1,test_data.shape[0]+1)]\n",
    "submit['Label'] = model.predict(test_data).argmax(axis=1)\n",
    "\n",
    "submit.to_csv('/code/mnist/submit.csv',index=False)"
   ]
  }
 ],
 "metadata": {
  "kernelspec": {
   "display_name": "Python 3",
   "language": "python",
   "name": "python3"
  },
  "language_info": {
   "codemirror_mode": {
    "name": "ipython",
    "version": 3
   },
   "file_extension": ".py",
   "mimetype": "text/x-python",
   "name": "python",
   "nbconvert_exporter": "python",
   "pygments_lexer": "ipython3",
   "version": "3.8.10"
  },
  "orig_nbformat": 4
 },
 "nbformat": 4,
 "nbformat_minor": 2
}
